Workbook

Sheet Client DB
A1: BRAND | B1: No of Locations | C1: COMPANY | D1: CONTACT PERSON | E1: EMAIL | F1: DESIGNATION | G1: MOBILE | H1: ADDRESS | I1: STATE | J1: COUNTRY | K1: POST CODE | L1: CREATED ON | M1: SALES
A2: The Brew House & Bake & Brew Cafe | B2: 40 | C2: Movida Group | M2: MANFRED
A3: PappaRich | B3: 83 | C3: PappaRich Malaysia Sdn Bhd | M3: MANFRED
A4: Bhai Jim Jum | B4: 5 | C4: Jim Jum Thai Hotpot Restaurant | M4: MANFRED
A5: CoolBlog | B5: 290 | C5: Coolblog Enterprise Sdn Bhd | M5: MANFRED
A6: Kluang Station | B6: 200 | C6: Kluang Station F&B Sdn Bhd | M6: MANFRED
A7: He & She Coffee | B7: 30 | C7: He & She Coffee Sdn Bhd | M7: MANFRED
A8: Kopi Saigon | B8: 200 | C8: Seruni Global Sdn Bhd. | M8: MANFRED
A9: NOTA Cafe | B9: 3 | C9: Nota Concepts Setia Alam Sdn Bhd | M9: MANFRED
A10: Lotteria | B10: 1 | C10: Serai Group | M10: MANFRED
A11: Serai | C11: Serai Group | M11: MANFRED
A12: Serai Thai | C12: Serai Group | M12: MANFRED
A13: Jibby & Co | C13: Serai Group | M13: MANFRED
A14: Jibby Chow | C14: Serai Group | M14: MANFRED
A15: Jibby East Grill | C15: Serai Group | M15: MANFRED
A16: Super Blode | C16: Serai Group | M16: MANFRED
A17: Jibby by Park | C17: Serai Group | M17: MANFRED
A18: Chum Chum Pizzeria | C18: Serai Group | M18: MANFRED
A19: Iola | C19: Serai Group | M19: MANFRED
A20: Serai Café | C20: Serai Group | M20: MANFRED
A21: Meet Bros | C21: Serai Group | M21: MANFRED
A22: Makamakan | C22: Serai Group | M22: MANFRED
... A25: Serai Chicken Rice | C25: Serai Group | M25: MANFRED
A26: Nyonya Colors, Bad Scones | B26: 13 | C26: Little Cravings Sdn Bhd | M26: MANFRED
A27: Eco Disposable Sdn Bhd | B27: 1 | C27: Eco Disposable Sdn Bhd | M27: MANFRED
A28: Humblefood | B28: 5 | C28: Humble Food Holdings Sdn. Bhd | M28: MANFRED
A29: Red Kettle | B29: 2 | M29: MANFRED
A30: El Ocho | B30: 3 | M30: MANFRED
A31: Coast & Roast by Fish &Co. | B31: 1 | M31: MANFRED
A32: Third Serving | B32: 1 | M32: MANFRED
A33: Siti Li | B33: 1 | M33: MANFRED
A34: Ohcha Matcha | B34: 7 | M34: MANFRED
A35: Mokkys Pizza | B35: 9 | M35: MANFRED
A36: EM's | B36: 2 | M36: MANFRED
A37: Boost Juice | B37: 170 | M37: MANFRED
A38: Ayam Gepuk | B38: 46 | C38: Top Global Food And Beverages Sdn Bhd | M38: SYAZWAN
A39: Bebeks by Top Global | C39: Top Global Food And Beverages Sdn Bhd
A40: Nak Nak | B40: 7 | M40: MANFRED
A41: K Fry | B41: 10 | M41: MANFRED
A42: Boran | B42: 1 | M42: MANFRED
...

Sheet Weekly Update
A1: DATE CREATED | B1: HUNTER | C1: COMPANY | D1: BRAND | E1: NO. OF LOCATION | F1: STATUS | G1: LAST CONTACT DATE | H1: CONTACT PERSON | I1: CONTACT TYPE | J1: NOTE | K1: FOLLOW UP REMINDER | L1: APPOINTMENT
A2: 46125 | B2: MANFRED | D2: Lotteria | F2: SUBSCRIBED | I2: FOLLOW UP MEETING | J2: Opening 2nd outlet in Sept 2026. | K2: 46223
A3: 46125 | B3: MANFRED | D3: Mee Tarik Jalan Sultan | F3: REJECTED | I3: STATUS UPDATE | K3: 46195
A4: 46125 | B4: MANFRED | D4: Dandy | F4: REJECTED | I4: FOLLOW UP CALL | K4: 46195
A5: 46125 | B5: MANFRED | D5: Ling Ling Long Long Gastrobar | F5: CONFIRMED | I5: FOLLOW UP CALL | J5: Still working on SI tagging | K5: 46223
A6: 46125 | B6: MANFRED | D6: Kissy Fish | F6: IN NEGO | I6: FOLLOW UP CALL | J6: Onboard 1st outlet Ling2 Long2 first. | K6: 46223
A7: 46125 | B7: MANFRED | D7: SuperNomms Fried Chicken | F7: PROPOSED | I7: FOLLOW UP CALL | J7: 6x outlets + 1x CK. Ops and CK head request for old quote and new quote to discuss with boss. | K7: 46223
A8: 46125 | B8: MANFRED | D8: Churros Plus | F8: KIV | I8: FOLLOW UP CALL | J8: FMH outlet average price is RM 1400/yr for 20 outlets. Setting meeting with client. | K8: 46223
A9: 46125 | B9: MANFRED | D9: Empire Sushi | F9: REJECTED | I9: FOLLOW UP CALL | K9: 46195
A10: 46125 | B10: MANFRED | D10: Tasty Chapathi | F10: IN NEGO | I10: FOLLOW UP CALL | J10: Did 2nd demo with client. Client to get back to us by end of the month to enjoy the previous quoted price. | K10: 46223
A11: 46125 | B11: MANFRED | D11: Sari Ratu Signature | F11: KIV | I11: FOLLOW UP CALL | J11: Client short of hand. Waiting for new staff to handle Bisync. | K11: 46223
A12: 46125 | B12: MANFRED | D12: Ali Muthu Ah Hock | F12: IN NEGO | I12: FOLLOW UP MEETING | J12: Following up with Edmund | K12: 46223
A13: 46125 | B13: MANFRED | D13: Michelangelo's | F13: PAID | I13: TRAINING | J13: Paid onboarding. Pending full payment after onboarded their SI and recipe. | K13: 46223
A14: 46125 | B14: MANFRED | D14: Dolly Dim Sum | F14: REJECTED | I14: FOLLOW UP CALL | K14: 46195
A15: 46125 | B15: MANFRED | D15: 1901 Hotdog Malaysia | F15: REJECTED | I15: FOLLOW UP CALL | K15: 46195
A16: 46006 | B16: DRA | D16: 4Fingers Crispy Chicken | F16: PROSPECT | I16: OFFLINE PRESENTATION | J16: MEETING WITH TEAM NEXT ROUND | K16: 46135
A17: 46146 | B17: KHAFIZ | D17: Cor Blimey | F17: REJECTED | I17: SALES MEETING | J17: 1st meeting on 4/5
A18: 46146 | B18: KHAFIZ | D18: Rendezvous Steak House | F18: REJECTED | I18: COLD CALL
A19: 46146 | B19: KHAFIZ | D19: Karaa Saraam | F19: LEAD | I19: COLD CALL
A20: 46146 | B20: KHAFIZ | D20: Sushi Zanmai | F20: LEAD | I20: EMAIL BLAST
A21: 46146 | B21: KHAFIZ | D21: Two Sons | F21: LEAD | I21: EMAIL BLAST
A22: 46146 | B22: KHAFIZ | D22: Oriental Kopi | F22: LEAD | I22: EMAIL BLAST
A23: 46146 | B23: KHAFIZ | D23: Hidang KL | F23: LEAD | I23: COLD CALL
A24: 46146 | B24: KHAFIZ | D24: Social | F24: LEAD | I24: EMAIL BLAST
A25: 46146 | B25: KHAFIZ | D25: Kampung Lah | F25: LEAD | I25: COLD CALL
A26: 46146 | B26: KHAFIZ | D26: Sushi King | F26: LEAD | I26: EMAIL BLAST | J26: Manage to get outlet manager number.will contact the pic and try to connect with the HQ side | K26: 46176
A27: 46146 | B27: KHAFIZ | D27: Baan 26 | F27: LEAD | I27: EMAIL BLAST
A28: 46146 | B28: KHAFIZ | D28: Sate Hut | F28: LEAD | I28: COLD CALL
A29: 46146 | B29: KHAFIZ | D29: Sate Haji Samuri | F29: REJECTED | I29: SALES MEETING | J29: Send Proposal to client
A30: 46146 | B30: MANFRED | D30: Hallaway | F30: PROPOSED | I30: FOLLOW UP MEETING | J30: Sent out quote for client to discuss with mgmt. / Follow up but no feedback from the top management | K30: 46223
A31: 46146 | B31: MANFRED | D31: OHO Thai Mookata & Bar | F31: PROPOSED | I31: FOLLOW UP MEETING | J31: Sent out quote for client to discuss with mgmt. | K31: 46223
A32: 46146 | B32: MANFRED | D32: Farmer and Chef Hotpot | F32: PROPOSED | I32: FOLLOW UP MEETING | J32: Sent out quote for client to discuss with mgmt. | K32: 46223
A33: 46146 | B33: MANFRED | D33: Ayam Gepuk Hut | F33: PROSPECT | I33: FOLLOW UP MEETING | J33: Waiting for client to share info to send out quote and set 2nd meeting with their bosses. | K33: 46223
A34: 46146 | B34: MANFRED | D34: Samudra Food | F34: PROSPECT | I34: FOLLOW UP MEETING | J34: Waiting for client to pass us their recipe details to onboard a demo process flow of PMS and set 2nd meeting with them. | K34: 46223
A35: 46146 | B35: MANFRED | D35: Big Onion Catering | F35: PROSPECT | I35: FOLLOW UP MEETING | J35: Reach out to Shah/Louise and no respond on call/text. Continue to reach out to them both. | K35: 46223
A36: 46146 | B36: MANFRED | D36: Kluang Rail Coffee | F36: LEAD | I36: FOLLOW UP MEETING | J36: Setting meeting. | K36: 46223
A37: 46146 | B37: MANFRED | D37: Kopi Street | F37: LEAD | I37: FOLLOW UP MEETING | J37: Setting meeting. | K37: 46223
A38: 46146 | B38: MANFRED | D38: Shihlin Taiwan Street Snacks | F38: REJECTED | I38: STATUS UPDATE | J38: SG HQ not considering this for now. | K38: 46198
A39: 46146 | B39: MANFRED | D39: BHC Chicken | F39: PROSPECT | I39: FOLLOW UP MEETING | J39: Send out proposal quote of 3 years for client. Client verbally wants to start onboarding on August 2026. | K39: 46223
A40: 46147 | B40: KHAFIZ | D40: House Of Kambing | F40: REJECTED | I40: DEMO | J40: Demo Set on 13/5 | K40: 46153
...

Sheet SYS LST
A1: Johor | B1: 0. LEAD | C1: COLD CALL | D1: EUGENE | E1: SUBSCRIPTION FEE | F1: MALAYSIA
A2: Kedah | B2: 1. PROSPECT | C2: EMAIL BLAST | D2: MANFRED | E2: CUSTOMIZATION | F2: SINGAPORE
A3: Kelantan | B3: 2. PROPOSED | C3: FOLLOW UP CALL | D3: WAN | E3: DEPOSIT
A4: Malacca | B4: 3. IN NEGO | C4: FOLLOW UP EMAIL | D4: DRA | E4: SUBSCRIPTION BALANCE
A5: Negeri Sembilan | B5: 4. CONFIRMED | C5: SALES MEETING | D5: TERRENCE | E5: SUPPORT FEE
A6: Pahang | B6: 5. INVOICED | C6: FOLLOW UP MEETING | D6: LENNY | E6: TRAINING
A7: Penang | B7: 6. PAID | C7: DEMO | D7: KHAFIZ
A8: Perak | B8: 7. SUBSCRIBED | C8: ONLINE PRESENTATION
A9: Perlis | B9: 8. KIV | C9: OFFLINE PRESENTATION | D9: ALL
A10: Sabah | B10: 9. REJECTED | C10: STATUS UPDATE
A11: Sarawak | C11: TRAINING
A12: Selangor | C12: POST MEETING
A13: Terengganu | C13: REGULAR CATCH UP
A14: Kuala Lumpur | C14: PAYMENT RECEIVED
A15: Putrajaya | C15: SUBCRIPTION STARTS
A16: Labuan

Sheet SUMMARY
A2: From | B2: =B3-(E2*7) -> 45985 | D2: NO OF WEEKS | E2: 20
A3: To | B3: 46125
A5: ACTIVITY | B5: ALL | C5: EUGENE | D5: MANFRED | E5: WAN | H5: DRA | J5: STATUS UPDATE
A6: ='SYS LST'!C1 -> COLD CALL | B6: =COUNTIFS('Weekly Update'!$A:$A,">="&SUMMARY!$B$2,'Weekly Update'!$A:$A,"<="&SUMMARY!$B$3,'Weekly Update'!$I:$I,A$6) -> 0 | C6: =COUNTIFS('Weekly Update'!$A:$A,">="&SUMMARY!$B$2,'Weekly Update'!$A:$A,"<="&SUMMARY!$B$3,'Weekly Update'!$I:$I,$A6,'Weekly Update'!$B:$B,SUMMARY!$C$5) -> 0 | D6: =COUNTIFS('Weekly Update'!$A:$A,">="&SUMMARY!$B$2,'Weekly Update'!$A:$A,"<="&SUMMARY!$B$3,'Weekly Update'!$I:$I,$A6,'Weekly Update'!$B:$B,SUMMARY!$D$5) -> 0 | E6: =COUNTIFS('Weekly Update'!$A:$A,">="&SUMMARY!$B$2,'Weekly Update'!$A:$A,"<="&SUMMARY!$B$3,'Weekly Update'!$I:$I,$A6,'Weekly Update'!$B:$B,SUMMARY!$E$5) -> 0 | F6: =COUNTIFS('Weekly Update'!$A:$A,">="&SUMMARY!$B$2,'Weekly Update'!$A:$A,"<="&SUMMARY!$B$3,'Weekly Update'!$I:$I,$A6,'Weekly Update'!$B:$B,SUMMARY!$F$5) -> 0 | G6: =COUNTIFS('Weekly Update'!$A:$A,">="&SUMMARY!$B$2,'Weekly Update'!$A:$A,"<="&SUMMARY!$B$3,'Weekly Update'!$I:$I,$A6,'Weekly Update'!$B:$B,SUMMARY!$G$5) -> 0 | H6: =COUNTIFS('Weekly Update'!$A:$A,">="&SUMMARY!$B$2,'Weekly Update'!$A:$A,"<="&SUMMARY!$B$3,'Weekly Update'!$I:$I,$A6,'Weekly Update'!$B:$B,SUMMARY!$H$5) -> 0 | J6: 0. LEAD | K6: =COUNTIFS('Weekly Update'!$A:$A,">="&SUMMARY!$B$2,'Weekly Update'!$A:$A,"<="&SUMMARY!$B$3,'Weekly Update'!$I:$I,$J$5,'Weekly Update'!$F:$F,$J6) -> 0
A7: ='SYS LST'!C2 -> EMAIL BLAST | B7: =COUNTIFS('Weekly Update'!$A:$A,">="&SUMMARY!$B$2,'Weekly Update'!$A:$A,"<="&SUMMARY!$B$3,'Weekly Update'!$I:$I,A7) -> 0 | C7: =COUNTIFS('Weekly Update'!$A:$A,">="&SUMMARY!$B$2,'Weekly Update'!$A:$A,"<="&SUMMARY!$B$3,'Weekly Update'!$I:$I,$A7,'Weekly Update'!$B:$B,SUMMARY!$C$5) -> 0 | D7: =COUNTIFS('Weekly Update'!$A:$A,">="&SUMMARY!$B$2,'Weekly Update'!$A:$A,"<="&SUMMARY!$B$3,'Weekly Update'!$I:$I,$A7,'Weekly Update'!$B:$B,SUMMARY!$D$5) -> 0 | E7: =COUNTIFS('Weekly Update'!$A:$A,">="&SUMMARY!$B$2,'Weekly Update'!$A:$A,"<="&SUMMARY!$B$3,'Weekly Update'!$I:$I,$A7,'Weekly Update'!$B:$B,SUMMARY!$E$5) -> 0 | F7: =COUNTIFS('Weekly Update'!$A:$A,">="&SUMMARY!$B$2,'Weekly Update'!$A:$A,"<="&SUMMARY!$B$3,'Weekly Update'!$I:$I,$A7,'Weekly Update'!$B:$B,SUMMARY!$F$5) -> 0 | G7: =COUNTIFS('Weekly Update'!$A:$A,">="&SUMMARY!$B$2,'Weekly Update'!$A:$A,"<="&SUMMARY!$B$3,'Weekly Update'!$I:$I,$A7,'Weekly Update'!$B:$B,SUMMARY!$G$5) -> 0 | H7: =COUNTIFS('Weekly Update'!$A:$A,">="&SUMMARY!$B$2,'Weekly Update'!$A:$A,"<="&SUMMARY!$B$3,'Weekly Update'!$I:$I,$A7,'Weekly Update'!$B:$B,SUMMARY!$H$5) -> 0 | J7: 1. PROSPECT | K7: =COUNTIFS('Weekly Update'!$A:$A,">="&SUMMARY!$B$2,'Weekly Update'!$A:$A,"<="&SUMMARY!$B$3,'Weekly Update'!$I:$I,$J$5,'Weekly Update'!$F:$F,$J7) -> 0
A8: ='SYS LST'!C3 -> FOLLOW UP CALL | B8: =COUNTIFS('Weekly Update'!$A:$A,">="&SUMMARY!$B$2,'Weekly Update'!$A:$A,"<="&SUMMARY!$B$3,'Weekly Update'!$I:$I,A8) -> 10 | C8: =COUNTIFS('Weekly Update'!$A:$A,">="&SUMMARY!$B$2,'Weekly Update'!$A:$A,"<="&SUMMARY!$B$3,'Weekly Update'!$I:$I,$A8,'Weekly Update'!$B:$B,SUMMARY!$C$5) -> 0 | D8: =COUNTIFS('Weekly Update'!$A:$A,">="&SUMMARY!$B$2,'Weekly Update'!$A:$A,"<="&SUMMARY!$B$3,'Weekly Update'!$I:$I,$A8,'Weekly Update'!$B:$B,SUMMARY!$D$5) -> 10 | E8: =COUNTIFS('Weekly Update'!$A:$A,">="&SUMMARY!$B$2,'Weekly Update'!$A:$A,"<="&SUMMARY!$B$3,'Weekly Update'!$I:$I,$A8,'Weekly Update'!$B:$B,SUMMARY!$E$5) -> 0 | F8: =COUNTIFS('Weekly Update'!$A:$A,">="&SUMMARY!$B$2,'Weekly Update'!$A:$A,"<="&SUMMARY!$B$3,'Weekly Update'!$I:$I,$A8,'Weekly Update'!$B:$B,SUMMARY!$F$5) -> 0 | G8: =COUNTIFS('Weekly Update'!$A:$A,">="&SUMMARY!$B$2,'Weekly Update'!$A:$A,"<="&SUMMARY!$B$3,'Weekly Update'!$I:$I,$A8,'Weekly Update'!$B:$B,SUMMARY!$G$5) -> 0 | H8: =COUNTIFS('Weekly Update'!$A:$A,">="&SUMMARY!$B$2,'Weekly Update'!$A:$A,"<="&SUMMARY!$B$3,'Weekly Update'!$I:$I,$A8,'Weekly Update'!$B:$B,SUMMARY!$H$5) -> 0 | J8: 2. PROPOSED | K8: =COUNTIFS('Weekly Update'!$A:$A,">="&SUMMARY!$B$2,'Weekly Update'!$A:$A,"<="&SUMMARY!$B$3,'Weekly Update'!$I:$I,$J$5,'Weekly Update'!$F:$F,$J8) -> 0
A9: ='SYS LST'!C4 -> FOLLOW UP EMAIL | B9: =COUNTIFS('Weekly Update'!$A:$A,">="&SUMMARY!$B$2,'Weekly Update'!$A:$A,"<="&SUMMARY!$B$3,'Weekly Update'!$I:$I,A9) -> 0 | C9: =COUNTIFS('Weekly Update'!$A:$A,">="&SUMMARY!$B$2,'Weekly Update'!$A:$A,"<="&SUMMARY!$B$3,'Weekly Update'!$I:$I,$A9,'Weekly Update'!$B:$B,SUMMARY!$C$5) -> 0 | D9: =COUNTIFS('Weekly Update'!$A:$A,">="&SUMMARY!$B$2,'Weekly Update'!$A:$A,"<="&SUMMARY!$B$3,'Weekly Update'!$I:$I,$A9,'Weekly Update'!$B:$B,SUMMARY!$D$5) -> 0 | E9: =COUNTIFS('Weekly Update'!$A:$A,">="&SUMMARY!$B$2,'Weekly Update'!$A:$A,"<="&SUMMARY!$B$3,'Weekly Update'!$I:$I,$A9,'Weekly Update'!$B:$B,SUMMARY!$E$5) -> 0 | F9: =COUNTIFS('Weekly Update'!$A:$A,">="&SUMMARY!$B$2,'Weekly Update'!$A:$A,"<="&SUMMARY!$B$3,'Weekly Update'!$I:$I,$A9,'Weekly Update'!$B:$B,SUMMARY!$F$5) -> 0 | G9: =COUNTIFS('Weekly Update'!$A:$A,">="&SUMMARY!$B$2,'Weekly Update'!$A:$A,"<="&SUMMARY!$B$3,'Weekly Update'!$I:$I,$A9,'Weekly Update'!$B:$B,SUMMARY!$G$5) -> 0 | H9: =COUNTIFS('Weekly Update'!$A:$A,">="&SUMMARY!$B$2,'Weekly Update'!$A:$A,"<="&SUMMARY!$B$3,'Weekly Update'!$I:$I,$A9,'Weekly Update'!$B:$B,SUMMARY!$H$5) -> 0 | J9: 3. CONFIRMED | K9: =COUNTIFS('Weekly Update'!$A:$A,">="&SUMMARY!$B$2,'Weekly Update'!$A:$A,"<="&SUMMARY!$B$3,'Weekly Update'!$I:$I,$J$5,'Weekly Update'!$F:$F,$J9) -> 0
A10: ='SYS LST'!C5 -> SALES MEETING | B10: =COUNTIFS('Weekly Update'!$A:$A,">="&SUMMARY!$B$2,'Weekly Update'!$A:$A,"<="&SUMMARY!$B$3,'Weekly Update'!$I:$I,A10) -> 0 | C10: =COUNTIFS('Weekly Update'!$A:$A,">="&SUMMARY!$B$2,'Weekly Update'!$A:$A,"<="&SUMMARY!$B$3,'Weekly Update'!$I:$I,$A10,'Weekly Update'!$B:$B,SUMMARY!$C$5) -> 0 | D10: =COUNTIFS('Weekly Update'!$A:$A,">="&SUMMARY!$B$2,'Weekly Update'!$A:$A,"<="&SUMMARY!$B$3,'Weekly Update'!$I:$I,$A10,'Weekly Update'!$B:$B,SUMMARY!$D$5) -> 0 | E10: =COUNTIFS('Weekly Update'!$A:$A,">="&SUMMARY!$B$2,'Weekly Update'!$A:$A,"<="&SUMMARY!$B$3,'Weekly Update'!$I:$I,$A10,'Weekly Update'!$B:$B,SUMMARY!$E$5) -> 0 | F10: =COUNTIFS('Weekly Update'!$A:$A,">="&SUMMARY!$B$2,'Weekly Update'!$A:$A,"<="&SUMMARY!$B$3,'Weekly Update'!$I:$I,$A10,'Weekly Update'!$B:$B,SUMMARY!$F$5) -> 0 | G10: =COUNTIFS('Weekly Update'!$A:$A,">="&SUMMARY!$B$2,'Weekly Update'!$A:$A,"<="&SUMMARY!$B$3,'Weekly Update'!$I:$I,$A10,'Weekly Update'!$B:$B,SUMMARY!$G$5) -> 0 | H10: =COUNTIFS('Weekly Update'!$A:$A,">="&SUMMARY!$B$2,'Weekly Update'!$A:$A,"<="&SUMMARY!$B$3,'Weekly Update'!$I:$I,$A10,'Weekly Update'!$B:$B,SUMMARY!$H$5) -> 0 | J10: 4. POC | K10: =COUNTIFS('Weekly Update'!$A:$A,">="&SUMMARY!$B$2,'Weekly Update'!$A:$A,"<="&SUMMARY!$B$3,'Weekly Update'!$I:$I,$J$5,'Weekly Update'!$F:$F,$J10) -> 0
A11: ='SYS LST'!C6 -> FOLLOW UP MEETING | B11: =COUNTIFS('Weekly Update'!$A:$A,">="&SUMMARY!$B$2,'Weekly Update'!$A:$A,"<="&SUMMARY!$B$3,'Weekly Update'!$I:$I,A11) -> 2 | C11: =COUNTIFS('Weekly Update'!$A:$A,">="&SUMMARY!$B$2,'Weekly Update'!$A:$A,"<="&SUMMARY!$B$3,'Weekly Update'!$I:$I,$A11,'Weekly Update'!$B:$B,SUMMARY!$C$5) -> 0 | D11: =COUNTIFS('Weekly Update'!$A:$A,">="&SUMMARY!$B$2,'Weekly Update'!$A:$A,"<="&SUMMARY!$B$3,'Weekly Update'!$I:$I,$A11,'Weekly Update'!$B:$B,SUMMARY!$D$5) -> 2 | E11: =COUNTIFS('Weekly Update'!$A:$A,">="&SUMMARY!$B$2,'Weekly Update'!$A:$A,"<="&SUMMARY!$B$3,'Weekly Update'!$I:$I,$A11,'Weekly Update'!$B:$B,SUMMARY!$E$5) -> 0 | F11: =COUNTIFS('Weekly Update'!$A:$A,">="&SUMMARY!$B$2,'Weekly Update'!$A:$A,"<="&SUMMARY!$B$3,'Weekly Update'!$I:$I,$A11,'Weekly Update'!$B:$B,SUMMARY!$F$5) -> 0 | G11: =COUNTIFS('Weekly Update'!$A:$A,">="&SUMMARY!$B$2,'Weekly Update'!$A:$A,"<="&SUMMARY!$B$3,'Weekly Update'!$I:$I,$A11,'Weekly Update'!$B:$B,SUMMARY!$G$5) -> 0 | H11: =COUNTIFS('Weekly Update'!$A:$A,">="&SUMMARY!$B$2,'Weekly Update'!$A:$A,"<="&SUMMARY!$B$3,'Weekly Update'!$I:$I,$A11,'Weekly Update'!$B:$B,SUMMARY!$H$5) -> 0 | J11: 5. INVOICED | K11: =COUNTIFS('Weekly Update'!$A:$A,">="&SUMMARY!$B$2,'Weekly Update'!$A:$A,"<="&SUMMARY!$B$3,'Weekly Update'!$I:$I,$J$5,'Weekly Update'!$F:$F,$J11) -> 0
A12: ='SYS LST'!C7 -> DEMO | B12: =COUNTIFS('Weekly Update'!$A:$A,">="&SUMMARY!$B$2,'Weekly Update'!$A:$A,"<="&SUMMARY!$B$3,'Weekly Update'!$I:$I,A12) -> 0 | C12: =COUNTIFS('Weekly Update'!$A:$A,">="&SUMMARY!$B$2,'Weekly Update'!$A:$A,"<="&SUMMARY!$B$3,'Weekly Update'!$I:$I,$A12,'Weekly Update'!$B:$B,SUMMARY!$C$5) -> 0 | D12: =COUNTIFS('Weekly Update'!$A:$A,">="&SUMMARY!$B$2,'Weekly Update'!$A:$A,"<="&SUMMARY!$B$3,'Weekly Update'!$I:$I,$A12,'Weekly Update'!$B:$B,SUMMARY!$D$5) -> 0 | E12: =COUNTIFS('Weekly Update'!$A:$A,">="&SUMMARY!$B$2,'Weekly Update'!$A:$A,"<="&SUMMARY!$B$3,'Weekly Update'!$I:$I,$A12,'Weekly Update'!$B:$B,SUMMARY!$E$5) -> 0 | F12: =COUNTIFS('Weekly Update'!$A:$A,">="&SUMMARY!$B$2,'Weekly Update'!$A:$A,"<="&SUMMARY!$B$3,'Weekly Update'!$I:$I,$A12,'Weekly Update'!$B:$B,SUMMARY!$F$5) -> 0 | G12: =COUNTIFS('Weekly Update'!$A:$A,">="&SUMMARY!$B$2,'Weekly Update'!$A:$A,"<="&SUMMARY!$B$3,'Weekly Update'!$I:$I,$A12,'Weekly Update'!$B:$B,SUMMARY!$G$5) -> 0 | H12: =COUNTIFS('Weekly Update'!$A:$A,">="&SUMMARY!$B$2,'Weekly Update'!$A:$A,"<="&SUMMARY!$B$3,'Weekly Update'!$I:$I,$A12,'Weekly Update'!$B:$B,SUMMARY!$H$5) -> 0 | J12: 6. PAID | K12: =COUNTIFS('Weekly Update'!$A:$A,">="&SUMMARY!$B$2,'Weekly Update'!$A:$A,"<="&SUMMARY!$B$3,'Weekly Update'!$I:$I,$J$5,'Weekly Update'!$F:$F,$J12) -> 0
A13: ='SYS LST'!C8 -> ONLINE PRESENTATION | B13: =COUNTIFS('Weekly Update'!$A:$A,">="&SUMMARY!$B$2,'Weekly Update'!$A:$A,"<="&SUMMARY!$B$3,'Weekly Update'!$I:$I,A13) -> 0 | C13: =COUNTIFS('Weekly Update'!$A:$A,">="&SUMMARY!$B$2,'Weekly Update'!$A:$A,"<="&SUMMARY!$B$3,'Weekly Update'!$I:$I,$A13,'Weekly Update'!$B:$B,SUMMARY!$C$5) -> 0 | D13: =COUNTIFS('Weekly Update'!$A:$A,">="&SUMMARY!$B$2,'Weekly Update'!$A:$A,"<="&SUMMARY!$B$3,'Weekly Update'!$I:$I,$A13,'Weekly Update'!$B:$B,SUMMARY!$D$5) -> 0 | E13: =COUNTIFS('Weekly Update'!$A:$A,">="&SUMMARY!$B$2,'Weekly Update'!$A:$A,"<="&SUMMARY!$B$3,'Weekly Update'!$I:$I,$A13,'Weekly Update'!$B:$B,SUMMARY!$E$5) -> 0 | F13: =COUNTIFS('Weekly Update'!$A:$A,">="&SUMMARY!$B$2,'Weekly Update'!$A:$A,"<="&SUMMARY!$B$3,'Weekly Update'!$I:$I,$A13,'Weekly Update'!$B:$B,SUMMARY!$F$5) -> 0 | G13: =COUNTIFS('Weekly Update'!$A:$A,">="&SUMMARY!$B$2,'Weekly Update'!$A:$A,"<="&SUMMARY!$B$3,'Weekly Update'!$I:$I,$A13,'Weekly Update'!$B:$B,SUMMARY!$G$5) -> 0 | H13: =COUNTIFS('Weekly Update'!$A:$A,">="&SUMMARY!$B$2,'Weekly Update'!$A:$A,"<="&SUMMARY!$B$3,'Weekly Update'!$I:$I,$A13,'Weekly Update'!$B:$B,SUMMARY!$H$5) -> 0 | J13: 7. SUBSCRIBED | K13: =COUNTIFS('Weekly Update'!$A:$A,">="&SUMMARY!$B$2,'Weekly Update'!$A:$A,"<="&SUMMARY!$B$3,'Weekly Update'!$I:$I,$J$5,'Weekly Update'!$F:$F,$J13) -> 0
A14: ='SYS LST'!C9 -> OFFLINE PRESENTATION | B14: =COUNTIFS('Weekly Update'!$A:$A,">="&SUMMARY!$B$2,'Weekly Update'!$A:$A,"<="&SUMMARY!$B$3,'Weekly Update'!$I:$I,A14) -> 1 | C14: =COUNTIFS('Weekly Update'!$A:$A,">="&SUMMARY!$B$2,'Weekly Update'!$A:$A,"<="&SUMMARY!$B$3,'Weekly Update'!$I:$I,$A14,'Weekly Update'!$B:$B,SUMMARY!$C$5) -> 0 | D14: =COUNTIFS('Weekly Update'!$A:$A,">="&SUMMARY!$B$2,'Weekly Update'!$A:$A,"<="&SUMMARY!$B$3,'Weekly Update'!$I:$I,$A14,'Weekly Update'!$B:$B,SUMMARY!$D$5) -> 0 | E14: =COUNTIFS('Weekly Update'!$A:$A,">="&SUMMARY!$B$2,'Weekly Update'!$A:$A,"<="&SUMMARY!$B$3,'Weekly Update'!$I:$I,$A14,'Weekly Update'!$B:$B,SUMMARY!$E$5) -> 0 | F14: =COUNTIFS('Weekly Update'!$A:$A,">="&SUMMARY!$B$2,'Weekly Update'!$A:$A,"<="&SUMMARY!$B$3,'Weekly Update'!$I:$I,$A14,'Weekly Update'!$B:$B,SUMMARY!$F$5) -> 0 | G14: =COUNTIFS('Weekly Update'!$A:$A,">="&SUMMARY!$B$2,'Weekly Update'!$A:$A,"<="&SUMMARY!$B$3,'Weekly Update'!$I:$I,$A14,'Weekly Update'!$B:$B,SUMMARY!$G$5) -> 0 | H14: =COUNTIFS('Weekly Update'!$A:$A,">="&SUMMARY!$B$2,'Weekly Update'!$A:$A,"<="&SUMMARY!$B$3,'Weekly Update'!$I:$I,$A14,'Weekly Update'!$B:$B,SUMMARY!$H$5) -> 1 | J14: 8. KIV | K14: =COUNTIFS('Weekly Update'!$A:$A,">="&SUMMARY!$B$2,'Weekly Update'!$A:$A,"<="&SUMMARY!$B$3,'Weekly Update'!$I:$I,$J$5,'Weekly Update'!$F:$F,$J14) -> 0
A15: ='SYS LST'!C10 -> STATUS UPDATE | B15: =COUNTIFS('Weekly Update'!$A:$A,">="&SUMMARY!$B$2,'Weekly Update'!$A:$A,"<="&SUMMARY!$B$3,'Weekly Update'!$I:$I,A15) -> 1 | C15: =COUNTIFS('Weekly Update'!$A:$A,">="&SUMMARY!$B$2,'Weekly Update'!$A:$A,"<="&SUMMARY!$B$3,'Weekly Update'!$I:$I,$A15,'Weekly Update'!$B:$B,SUMMARY!$C$5) -> 0 | D15: =COUNTIFS('Weekly Update'!$A:$A,">="&SUMMARY!$B$2,'Weekly Update'!$A:$A,"<="&SUMMARY!$B$3,'Weekly Update'!$I:$I,$A15,'Weekly Update'!$B:$B,SUMMARY!$D$5) -> 1 | E15: =COUNTIFS('Weekly Update'!$A:$A,">="&SUMMARY!$B$2,'Weekly Update'!$A:$A,"<="&SUMMARY!$B$3,'Weekly Update'!$I:$I,$A15,'Weekly Update'!$B:$B,SUMMARY!$E$5) -> 0 | F15: =COUNTIFS('Weekly Update'!$A:$A,">="&SUMMARY!$B$2,'Weekly Update'!$A:$A,"<="&SUMMARY!$B$3,'Weekly Update'!$I:$I,$A15,'Weekly Update'!$B:$B,SUMMARY!$F$5) -> 0 | G15: =COUNTIFS('Weekly Update'!$A:$A,">="&SUMMARY!$B$2,'Weekly Update'!$A:$A,"<="&SUMMARY!$B$3,'Weekly Update'!$I:$I,$A15,'Weekly Update'!$B:$B,SUMMARY!$G$5) -> 0 | H15: =COUNTIFS('Weekly Update'!$A:$A,">="&SUMMARY!$B$2,'Weekly Update'!$A:$A,"<="&SUMMARY!$B$3,'Weekly Update'!$I:$I,$A15,'Weekly Update'!$B:$B,SUMMARY!$H$5) -> 0 | J15: 9. REJECTED | K15: =COUNTIFS('Weekly Update'!$A:$A,">="&SUMMARY!$B$2,'Weekly Update'!$A:$A,"<="&SUMMARY!$B$3,'Weekly Update'!$I:$I,$J$5,'Weekly Update'!$F:$F,$J15) -> 0
A16: ='SYS LST'!C11 -> TRAINING | B16: =COUNTIFS('Weekly Update'!$A:$A,">="&SUMMARY!$B$2,'Weekly Update'!$A:$A,"<="&SUMMARY!$B$3,'Weekly Update'!$I:$I,A16) -> 1 | C16: =COUNTIFS('Weekly Update'!$A:$A,">="&SUMMARY!$B$2,'Weekly Update'!$A:$A,"<="&SUMMARY!$B$3,'Weekly Update'!$I:$I,$A16,'Weekly Update'!$B:$B,SUMMARY!$C$5) -> 0 | D16: =COUNTIFS('Weekly Update'!$A:$A,">="&SUMMARY!$B$2,'Weekly Update'!$A:$A,"<="&SUMMARY!$B$3,'Weekly Update'!$I:$I,$A16,'Weekly Update'!$B:$B,SUMMARY!$D$5) -> 1 | E16: =COUNTIFS('Weekly Update'!$A:$A,">="&SUMMARY!$B$2,'Weekly Update'!$A:$A,"<="&SUMMARY!$B$3,'Weekly Update'!$I:$I,$A16,'Weekly Update'!$B:$B,SUMMARY!$E$5) -> 0 | F16: =COUNTIFS('Weekly Update'!$A:$A,">="&SUMMARY!$B$2,'Weekly Update'!$A:$A,"<="&SUMMARY!$B$3,'Weekly Update'!$I:$I,$A16,'Weekly Update'!$B:$B,SUMMARY!$F$5) -> 0 | G16: =COUNTIFS('Weekly Update'!$A:$A,">="&SUMMARY!$B$2,'Weekly Update'!$A:$A,"<="&SUMMARY!$B$3,'Weekly Update'!$I:$I,$A16,'Weekly Update'!$B:$B,SUMMARY!$G$5) -> 0 | H16: =COUNTIFS('Weekly Update'!$A:$A,">="&SUMMARY!$B$2,'Weekly Update'!$A:$A,"<="&SUMMARY!$B$3,'Weekly Update'!$I:$I,$A16,'Weekly Update'!$B:$B,SUMMARY!$H$5) -> 0
A17: ='SYS LST'!C12 -> POST MEETING | B17: =COUNTIFS('Weekly Update'!$A:$A,">="&SUMMARY!$B$2,'Weekly Update'!$A:$A,"<="&SUMMARY!$B$3,'Weekly Update'!$I:$I,A17) -> 0 | C17: =COUNTIFS('Weekly Update'!$A:$A,">="&SUMMARY!$B$2,'Weekly Update'!$A:$A,"<="&SUMMARY!$B$3,'Weekly Update'!$I:$I,$A17,'Weekly Update'!$B:$B,SUMMARY!$C$5) -> 0 | D17: =COUNTIFS('Weekly Update'!$A:$A,">="&SUMMARY!$B$2,'Weekly Update'!$A:$A,"<="&SUMMARY!$B$3,'Weekly Update'!$I:$I,$A17,'Weekly Update'!$B:$B,SUMMARY!$D$5) -> 0 | E17: =COUNTIFS('Weekly Update'!$A:$A,">="&SUMMARY!$B$2,'Weekly Update'!$A:$A,"<="&SUMMARY!$B$3,'Weekly Update'!$I:$I,$A17,'Weekly Update'!$B:$B,SUMMARY!$E$5) -> 0 | F17: =COUNTIFS('Weekly Update'!$A:$A,">="&SUMMARY!$B$2,'Weekly Update'!$A:$A,"<="&SUMMARY!$B$3,'Weekly Update'!$I:$I,$A17,'Weekly Update'!$B:$B,SUMMARY!$F$5) -> 0 | G17: =COUNTIFS('Weekly Update'!$A:$A,">="&SUMMARY!$B$2,'Weekly Update'!$A:$A,"<="&SUMMARY!$B$3,'Weekly Update'!$I:$I,$A17,'Weekly Update'!$B:$B,SUMMARY!$G$5) -> 0 | H17: =COUNTIFS('Weekly Update'!$A:$A,">="&SUMMARY!$B$2,'Weekly Update'!$A:$A,"<="&SUMMARY!$B$3,'Weekly Update'!$I:$I,$A17,'Weekly Update'!$B:$B,SUMMARY!$H$5) -> 0
A18: ='SYS LST'!C13 -> REGULAR CATCH UP | B18: =COUNTIFS('Weekly Update'!$A:$A,">="&SUMMARY!$B$2,'Weekly Update'!$A:$A,"<="&SUMMARY!$B$3,'Weekly Update'!$I:$I,A18) -> 0 | C18: =COUNTIFS('Weekly Update'!$A:$A,">="&SUMMARY!$B$2,'Weekly Update'!$A:$A,"<="&SUMMARY!$B$3,'Weekly Update'!$I:$I,$A18,'Weekly Update'!$B:$B,SUMMARY!$C$5) -> 0 | D18: =COUNTIFS('Weekly Update'!$A:$A,">="&SUMMARY!$B$2,'Weekly Update'!$A:$A,"<="&SUMMARY!$B$3,'Weekly Update'!$I:$I,$A18,'Weekly Update'!$B:$B,SUMMARY!$D$5) -> 0 | E18: =COUNTIFS('Weekly Update'!$A:$A,">="&SUMMARY!$B$2,'Weekly Update'!$A:$A,"<="&SUMMARY!$B$3,'Weekly Update'!$I:$I,$A18,'Weekly Update'!$B:$B,SUMMARY!$E$5) -> 0 | F18: =COUNTIFS('Weekly Update'!$A:$A,">="&SUMMARY!$B$2,'Weekly Update'!$A:$A,"<="&SUMMARY!$B$3,'Weekly Update'!$I:$I,$A18,'Weekly Update'!$B:$B,SUMMARY!$F$5) -> 0 | G18: =COUNTIFS('Weekly Update'!$A:$A,">="&SUMMARY!$B$2,'Weekly Update'!$A:$A,"<="&SUMMARY!$B$3,'Weekly Update'!$I:$I,$A18,'Weekly Update'!$B:$B,SUMMARY!$G$5) -> 0 | H18: =COUNTIFS('Weekly Update'!$A:$A,">="&SUMMARY!$B$2,'Weekly Update'!$A:$A,"<="&SUMMARY!$B$3,'Weekly Update'!$I:$I,$A18,'Weekly Update'!$B:$B,SUMMARY!$H$5) -> 0
A19: ='SYS LST'!C14 -> PAYMENT RECEIVED | B19: =COUNTIFS('Weekly Update'!$A:$A,">="&SUMMARY!$B$2,'Weekly Update'!$A:$A,"<="&SUMMARY!$B$3,'Weekly Update'!$I:$I,A19) -> 0 | C19: =COUNTIFS('Weekly Update'!$A:$A,">="&SUMMARY!$B$2,'Weekly Update'!$A:$A,"<="&SUMMARY!$B$3,'Weekly Update'!$I:$I,$A19,'Weekly Update'!$B:$B,SUMMARY!$C$5) -> 0 | D19: =COUNTIFS('Weekly Update'!$A:$A,">="&SUMMARY!$B$2,'Weekly Update'!$A:$A,"<="&SUMMARY!$B$3,'Weekly Update'!$I:$I,$A19,'Weekly Update'!$B:$B,SUMMARY!$D$5) -> 0 | E19: =COUNTIFS('Weekly Update'!$A:$A,">="&SUMMARY!$B$2,'Weekly Update'!$A:$A,"<="&SUMMARY!$B$3,'Weekly Update'!$I:$I,$A19,'Weekly Update'!$B:$B,SUMMARY!$E$5) -> 0 | F19: =COUNTIFS('Weekly Update'!$A:$A,">="&SUMMARY!$B$2,'Weekly Update'!$A:$A,"<="&SUMMARY!$B$3,'Weekly Update'!$I:$I,$A19,'Weekly Update'!$B:$B,SUMMARY!$F$5) -> 0 | G19: =COUNTIFS('Weekly Update'!$A:$A,">="&SUMMARY!$B$2,'Weekly Update'!$A:$A,"<="&SUMMARY!$B$3,'Weekly Update'!$I:$I,$A19,'Weekly Update'!$B:$B,SUMMARY!$G$5) -> 0 | H19: =COUNTIFS('Weekly Update'!$A:$A,">="&SUMMARY!$B$2,'Weekly Update'!$A:$A,"<="&SUMMARY!$B$3,'Weekly Update'!$I:$I,$A19,'Weekly Update'!$B:$B,SUMMARY!$H$5) -> 0
A20: ='SYS LST'!C15 -> SUBCRIPTION STARTS | B20: =COUNTIFS('Weekly Update'!$A:$A,">="&SUMMARY!$B$2,'Weekly Update'!$A:$A,"<="&SUMMARY!$B$3,'Weekly Update'!$I:$I,A20) -> 0 | C20: =COUNTIFS('Weekly Update'!$A:$A,">="&SUMMARY!$B$2,'Weekly Update'!$A:$A,"<="&SUMMARY!$B$3,'Weekly Update'!$I:$I,$A20,'Weekly Update'!$B:$B,SUMMARY!$C$5) -> 0 | D20: =COUNTIFS('Weekly Update'!$A:$A,">="&SUMMARY!$B$2,'Weekly Update'!$A:$A,"<="&SUMMARY!$B$3,'Weekly Update'!$I:$I,$A20,'Weekly Update'!$B:$B,SUMMARY!$D$5) -> 0 | E20: =COUNTIFS('Weekly Update'!$A:$A,">="&SUMMARY!$B$2,'Weekly Update'!$A:$A,"<="&SUMMARY!$B$3,'Weekly Update'!$I:$I,$A20,'Weekly Update'!$B:$B,SUMMARY!$E$5) -> 0 | F20: =COUNTIFS('Weekly Update'!$A:$A,">="&SUMMARY!$B$2,'Weekly Update'!$A:$A,"<="&SUMMARY!$B$3,'Weekly Update'!$I:$I,$A20,'Weekly Update'!$B:$B,SUMMARY!$F$5) -> 0 | G20: =COUNTIFS('Weekly Update'!$A:$A,">="&SUMMARY!$B$2,'Weekly Update'!$A:$A,"<="&SUMMARY!$B$3,'Weekly Update'!$I:$I,$A20,'Weekly Update'!$B:$B,SUMMARY!$G$5) -> 0 | H20: =COUNTIFS('Weekly Update'!$A:$A,">="&SUMMARY!$B$2,'Weekly Update'!$A:$A,"<="&SUMMARY!$B$3,'Weekly Update'!$I:$I,$A20,'Weekly Update'!$B:$B,SUMMARY!$H$5) -> 0
